<?xml version="1.0" encoding="utf-8"?>
<!-- This URDF was automatically created by SolidWorks to URDF Exporter! Originally created by Stephen Brawner (brawner@gmail.com) 
     Commit Version: 1.6.0-1-g15f4949  Build Version: 1.6.7594.29634
     For more information, please see http://wiki.ros.org/sw_urdf_exporter -->
<robot
  name="brdl-millihexapod-ros">
  <link
    name="torso">
    <inertial>
      <origin
        xyz="8.334E-17 -0.00025 6.3375E-17"
        rpy="0 0 0" />
      <mass
        value="0.00532" />
      <inertia
        ixx="2.8094E-06"
        ixy="1.2681E-24"
        ixz="-1.1543E-19"
        iyy="1.6662E-05"
        iyz="-1.7216E-22"
        izz="1.3852E-05" />
    </inertial>
    <visual>
      <origin
        xyz="0 0 0"
        rpy="0 0 0" />
      <geometry>
        <mesh
          filename="package://brdl-millihexapod-ros/meshes/torso.STL" />
      </geometry>
      <material
        name="">
        <color
          rgba="0.79216 0.81961 0.93333 1" />
      </material>
    </visual>
    <collision>
      <origin
        xyz="0 0 0"
        rpy="0 0 0" />
      <geometry>
        <mesh
          filename="package://brdl-millihexapod-ros/meshes/torso.STL" />
      </geometry>
    </collision>
  </link>
  <link
    name="leg1_link1">
    <inertial>
      <origin
        xyz="-0.01 0.00025 -0.015"
        rpy="0 0 0" />
      <mass
        value="0.0003" />
      <inertia
        ixx="2.2506E-08"
        ixy="-6.5794E-27"
        ixz="4.6807E-23"
        iyy="3.25E-08"
        iyz="-7.6299E-27"
        izz="1.0006E-08" />
    </inertial>
    <visual>
      <origin
        xyz="0 0 0"
        rpy="0 0 0" />
      <geometry>
        <mesh
          filename="package://brdl-millihexapod-ros/meshes/leg1_link1.STL" />
      </geometry>
      <material
        name="">
        <color
          rgba="0.79216 0.81961 0.93333 1" />
      </material>
    </visual>
    <collision>
      <origin
        xyz="0 0 0"
        rpy="0 0 0" />
      <geometry>
        <mesh
          filename="package://brdl-millihexapod-ros/meshes/leg1_link1.STL" />
      </geometry>
    </collision>
  </link>
  <joint
    name="torso__leg1_link1"
    type="revolute">
    <origin
      xyz="0.04309 0 0.05"
      rpy="3.1416 1.5708 0" />
    <parent
      link="torso" />
    <child
      link="leg1_link1" />
    <axis
      xyz="0 0 1" />
    <limit
      lower="-3.14"
      upper="3.14"
      effort="10"
      velocity="10" />
  </joint>
  <link
    name="leg1_link2">
    <inertial>
      <origin
        xyz="-0.015 0.00025 -0.01"
        rpy="0 0 0" />
      <mass
        value="0.0003" />
      <inertia
        ixx="1.0006E-08"
        ixy="-8.6524E-26"
        ixz="1.1819E-23"
        iyy="3.25E-08"
        iyz="-1.0251E-24"
        izz="2.2506E-08" />
    </inertial>
    <visual>
      <origin
        xyz="0 0 0"
        rpy="0 0 0" />
      <geometry>
        <mesh
          filename="package://brdl-millihexapod-ros/meshes/leg1_link2.STL" />
      </geometry>
      <material
        name="">
        <color
          rgba="0.79216 0.81961 0.93333 1" />
      </material>
    </visual>
    <collision>
      <origin
        xyz="0 0 0"
        rpy="0 0 0" />
      <geometry>
        <mesh
          filename="package://brdl-millihexapod-ros/meshes/leg1_link2.STL" />
      </geometry>
    </collision>
  </link>
  <joint
    name="leg1_link1__leg1_link2"
    type="revolute">
    <origin
      xyz="-0.005 0 -0.03"
      rpy="0 0 0" />
    <parent
      link="leg1_link1" />
    <child
      link="leg1_link2" />
    <axis
      xyz="1 0 0" />
    <limit
      lower="-3.14"
      upper="3.14"
      effort="10"
      velocity="10" />
  </joint>
  <link
    name="leg1_link3">
    <inertial>
      <origin
        xyz="-0.0175 0.00025 -0.01"
        rpy="0 0 0" />
      <mass
        value="0.00035" />
      <inertia
        ixx="1.1674E-08"
        ixy="-6.1463E-27"
        ixz="3.4447E-24"
        iyy="4.7396E-08"
        iyz="-6.5907E-24"
        izz="3.5736E-08" />
    </inertial>
    <visual>
      <origin
        xyz="0 0 0"
        rpy="0 0 0" />
      <geometry>
        <mesh
          filename="package://brdl-millihexapod-ros/meshes/leg1_link3.STL" />
      </geometry>
      <material
        name="">
        <color
          rgba="0.79216 0.81961 0.93333 1" />
      </material>
    </visual>
    <collision>
      <origin
        xyz="0 0 0"
        rpy="0 0 0" />
      <geometry>
        <mesh
          filename="package://brdl-millihexapod-ros/meshes/leg1_link3.STL" />
      </geometry>
    </collision>
  </link>
  <joint
    name="leg1_link2__leg1_link3"
    type="revolute">
    <origin
      xyz="-0.03 0 0"
      rpy="0 0 0" />
    <parent
      link="leg1_link2" />
    <child
      link="leg1_link3" />
    <axis
      xyz="0 0 1" />
    <limit
      lower="-3.14"
      upper="3.14"
      effort="10"
      velocity="10" />
  </joint>
  <link
    name="leg2_link1">
    <inertial>
      <origin
        xyz="-0.01 0.00025 0.015"
        rpy="0 0 0" />
      <mass
        value="0.0003" />
      <inertia
        ixx="2.2506E-08"
        ixy="-8.6712E-26"
        ixz="4.1819E-24"
        iyy="3.25E-08"
        iyz="-9.0873E-27"
        izz="1.0006E-08" />
    </inertial>
    <visual>
      <origin
        xyz="0 0 0"
        rpy="0 0 0" />
      <geometry>
        <mesh
          filename="package://brdl-millihexapod-ros/meshes/leg2_link1.STL" />
      </geometry>
      <material
        name="">
        <color
          rgba="0.79216 0.81961 0.93333 1" />
      </material>
    </visual>
    <collision>
      <origin
        xyz="0 0 0"
        rpy="0 0 0" />
      <geometry>
        <mesh
          filename="package://brdl-millihexapod-ros/meshes/leg2_link1.STL" />
      </geometry>
    </collision>
  </link>
  <joint
    name="torso__leg2_link1"
    type="revolute">
    <origin
      xyz="0.01309 0 0.05"
      rpy="3.1416 1.5708 0" />
    <parent
      link="torso" />
    <child
      link="leg2_link1" />
    <axis
      xyz="0 0 1" />
    <limit
      lower="-3.14"
      upper="3.14"
      effort="10"
      velocity="10" />
  </joint>
  <link
    name="leg2_link2">
    <inertial>
      <origin
        xyz="-0.015 0.00025 -0.01"
        rpy="0 0 0" />
      <mass
        value="0.0003" />
      <inertia
        ixx="1.0006E-08"
        ixy="-4.4374E-26"
        ixz="1.3414E-23"
        iyy="3.25E-08"
        iyz="-1.4698E-24"
        izz="2.2506E-08" />
    </inertial>
    <visual>
      <origin
        xyz="0 0 0"
        rpy="0 0 0" />
      <geometry>
        <mesh
          filename="package://brdl-millihexapod-ros/meshes/leg2_link2.STL" />
      </geometry>
      <material
        name="">
        <color
          rgba="0.79216 0.81961 0.93333 1" />
      </material>
    </visual>
    <collision>
      <origin
        xyz="0 0 0"
        rpy="0 0 0" />
      <geometry>
        <mesh
          filename="package://brdl-millihexapod-ros/meshes/leg2_link2.STL" />
      </geometry>
    </collision>
  </link>
  <joint
    name="leg2_link1__leg2_link2"
    type="revolute">
    <origin
      xyz="-0.005 0 0"
      rpy="0 0 0" />
    <parent
      link="leg2_link1" />
    <child
      link="leg2_link2" />
    <axis
      xyz="1 0 0" />
    <limit
      lower="-3.14"
      upper="3.14"
      effort="10"
      velocity="10" />
  </joint>
  <link
    name="leg2_link3">
    <inertial>
      <origin
        xyz="-0.0174999999999999 0.00024999999999955 -0.0100000000000001"
        rpy="0 0 0" />
      <mass
        value="0.00035" />
      <inertia
        ixx="1.16739583333333E-08"
        ixy="2.05479604215668E-27"
        ixz="2.70955539200844E-23"
        iyy="4.73958333333336E-08"
        iyz="-1.71952008903282E-24"
        izz="3.57364583333336E-08" />
    </inertial>
    <visual>
      <origin
        xyz="0 0 0"
        rpy="0 0 0" />
      <geometry>
        <mesh
          filename="package://brdl-millihexapod-ros/meshes/leg2_link3.STL" />
      </geometry>
      <material
        name="">
        <color
          rgba="0.792156862745098 0.819607843137255 0.933333333333333 1" />
      </material>
    </visual>
    <collision>
      <origin
        xyz="0 0 0"
        rpy="0 0 0" />
      <geometry>
        <mesh
          filename="package://brdl-millihexapod-ros/meshes/leg2_link3.STL" />
      </geometry>
    </collision>
  </link>
  <joint
    name="leg2_link2__leg2_link3"
    type="revolute">
    <origin
      xyz="-0.03 0 0"
      rpy="0 0 0" />
    <parent
      link="leg2_link2" />
    <child
      link="leg2_link3" />
    <axis
      xyz="0 0 1" />
    <limit
      lower="-3.14"
      upper="3.14"
      effort="10"
      velocity="10" />
  </joint>
  <link
    name="leg3_link1">
    <inertial>
      <origin
        xyz="-0.01 0.00025 0.0150000000000001"
        rpy="0 0 0" />
      <mass
        value="0.0003" />
      <inertia
        ixx="2.250625E-08"
        ixy="-2.38122799040218E-26"
        ixz="-2.72407052268251E-23"
        iyy="3.24999999999999E-08"
        iyz="9.51731954648501E-27"
        izz="1.00062499999999E-08" />
    </inertial>
    <visual>
      <origin
        xyz="0 0 0"
        rpy="0 0 0" />
      <geometry>
        <mesh
          filename="package://brdl-millihexapod-ros/meshes/leg3_link1.STL" />
      </geometry>
      <material
        name="">
        <color
          rgba="0.792156862745098 0.819607843137255 0.933333333333333 1" />
      </material>
    </visual>
    <collision>
      <origin
        xyz="0 0 0"
        rpy="0 0 0" />
      <geometry>
        <mesh
          filename="package://brdl-millihexapod-ros/meshes/leg3_link1.STL" />
      </geometry>
    </collision>
  </link>
  <joint
    name="torso__leg3_link1"
    type="revolute">
    <origin
      xyz="-0.04691 0 0.05"
      rpy="3.1416 1.5708 0" />
    <parent
      link="torso" />
    <child
      link="leg3_link1" />
    <axis
      xyz="0 0 1" />
    <limit
      lower="-3.14"
      upper="3.14"
      effort="10"
      velocity="10" />
  </joint>
  <link
    name="leg3_link2">
    <inertial>
      <origin
        xyz="-0.015 0.00025 -0.00999999999999999"
        rpy="0 0 0" />
      <mass
        value="0.0003" />
      <inertia
        ixx="1.000625E-08"
        ixy="4.30431456475191E-26"
        ixz="2.33685637065344E-23"
        iyy="3.24999999999999E-08"
        iyz="1.65365611491139E-24"
        izz="2.250625E-08" />
    </inertial>
    <visual>
      <origin
        xyz="0 0 0"
        rpy="0 0 0" />
      <geometry>
        <mesh
          filename="package://brdl-millihexapod-ros/meshes/leg3_link2.STL" />
      </geometry>
      <material
        name="">
        <color
          rgba="0.792156862745098 0.819607843137255 0.933333333333333 1" />
      </material>
    </visual>
    <collision>
      <origin
        xyz="0 0 0"
        rpy="0 0 0" />
      <geometry>
        <mesh
          filename="package://brdl-millihexapod-ros/meshes/leg3_link2.STL" />
      </geometry>
    </collision>
  </link>
  <joint
    name="leg3_link1__leg3_link2"
    type="revolute">
    <origin
      xyz="-0.005 0 0"
      rpy="0 0 0" />
    <parent
      link="leg3_link1" />
    <child
      link="leg3_link2" />
    <axis
      xyz="1 0 0" />
    <limit
      lower="-3.14"
      upper="3.14"
      effort="10"
      velocity="10" />
  </joint>
  <link
    name="leg3_link3">
    <inertial>
      <origin
        xyz="-0.0175 0.000249999999999649 -0.0100000000000002"
        rpy="0 0 0" />
      <mass
        value="0.00035" />
      <inertia
        ixx="1.16739583333333E-08"
        ixy="-9.29196036004443E-26"
        ixz="2.90973796395913E-23"
        iyy="4.73958333333334E-08"
        iyz="-3.43187524152249E-24"
        izz="3.57364583333334E-08" />
    </inertial>
    <visual>
      <origin
        xyz="0 0 0"
        rpy="0 0 0" />
      <geometry>
        <mesh
          filename="package://brdl-millihexapod-ros/meshes/leg3_link3.STL" />
      </geometry>
      <material
        name="">
        <color
          rgba="0.792156862745098 0.819607843137255 0.933333333333333 1" />
      </material>
    </visual>
    <collision>
      <origin
        xyz="0 0 0"
        rpy="0 0 0" />
      <geometry>
        <mesh
          filename="package://brdl-millihexapod-ros/meshes/leg3_link3.STL" />
      </geometry>
    </collision>
  </link>
  <joint
    name="leg3_link2__leg3_link3"
    type="revolute">
    <origin
      xyz="-0.03 0 0"
      rpy="0 0 0" />
    <parent
      link="leg3_link2" />
    <child
      link="leg3_link3" />
    <axis
      xyz="0 0 1" />
    <limit
      lower="-3.14"
      upper="3.14"
      effort="10"
      velocity="10" />
  </joint>
  <link
    name="leg4_link1">
    <inertial>
      <origin
        xyz="0.01 0.00025 -0.0150000000000002"
        rpy="0 0 0" />
      <mass
        value="0.0003" />
      <inertia
        ixx="2.250625E-08"
        ixy="8.18316765689817E-26"
        ixz="-1.40645077507073E-23"
        iyy="3.25E-08"
        iyz="-3.70042776330073E-26"
        izz="1.000625E-08" />
    </inertial>
    <visual>
      <origin
        xyz="0 0 0"
        rpy="0 0 0" />
      <geometry>
        <mesh
          filename="package://brdl-millihexapod-ros/meshes/leg4_link1.STL" />
      </geometry>
      <material
        name="">
        <color
          rgba="0.792156862745098 0.819607843137255 0.933333333333333 1" />
      </material>
    </visual>
    <collision>
      <origin
        xyz="0 0 0"
        rpy="0 0 0" />
      <geometry>
        <mesh
          filename="package://brdl-millihexapod-ros/meshes/leg4_link1.STL" />
      </geometry>
    </collision>
  </link>
  <joint
    name="torso__leg4_link1"
    type="revolute">
    <origin
      xyz="0.04309 0 -0.05"
      rpy="3.1416 1.5708 0" />
    <parent
      link="torso" />
    <child
      link="leg4_link1" />
    <axis
      xyz="0 0 1" />
    <limit
      lower="-3.14"
      upper="3.14"
      effort="10"
      velocity="10" />
  </joint>
  <link
    name="leg4_link2">
    <inertial>
      <origin
        xyz="0.015 0.000249999999999998 -0.01"
        rpy="0 0 0" />
      <mass
        value="0.0003" />
      <inertia
        ixx="1.000625E-08"
        ixy="-3.38582644772895E-26"
        ixz="9.83581448732817E-24"
        iyy="3.25E-08"
        iyz="-1.11345588583405E-24"
        izz="2.250625E-08" />
    </inertial>
    <visual>
      <origin
        xyz="0 0 0"
        rpy="0 0 0" />
      <geometry>
        <mesh
          filename="package://brdl-millihexapod-ros/meshes/leg4_link2.STL" />
      </geometry>
      <material
        name="">
        <color
          rgba="0.792156862745098 0.819607843137255 0.933333333333333 1" />
      </material>
    </visual>
    <collision>
      <origin
        xyz="0 0 0"
        rpy="0 0 0" />
      <geometry>
        <mesh
          filename="package://brdl-millihexapod-ros/meshes/leg4_link2.STL" />
      </geometry>
    </collision>
  </link>
  <joint
    name="leg4_link1__leg4_link2"
    type="revolute">
    <origin
      xyz="0.005 0 -0.03"
      rpy="0 0 0" />
    <parent
      link="leg4_link1" />
    <child
      link="leg4_link2" />
    <axis
      xyz="1 0 0" />
    <limit
      lower="-3.14"
      upper="3.14"
      effort="10"
      velocity="10" />
  </joint>
  <link
    name="leg4_link3">
    <inertial>
      <origin
        xyz="0.0174999999999999 0.000249999999999998 -0.0100000000000003"
        rpy="0 0 0" />
      <mass
        value="0.00035" />
      <inertia
        ixx="1.16739583333333E-08"
        ixy="-2.2098271413235E-25"
        ixz="-8.07571900902903E-24"
        iyy="4.73958333333335E-08"
        iyz="1.46198146142568E-24"
        izz="3.57364583333335E-08" />
    </inertial>
    <visual>
      <origin
        xyz="0 0 0"
        rpy="0 0 0" />
      <geometry>
        <mesh
          filename="package://brdl-millihexapod-ros/meshes/leg4_link3.STL" />
      </geometry>
      <material
        name="">
        <color
          rgba="0.792156862745098 0.819607843137255 0.933333333333333 1" />
      </material>
    </visual>
    <collision>
      <origin
        xyz="0 0 0"
        rpy="0 0 0" />
      <geometry>
        <mesh
          filename="package://brdl-millihexapod-ros/meshes/leg4_link3.STL" />
      </geometry>
    </collision>
  </link>
  <joint
    name="leg4_link2__leg4_link3"
    type="revolute">
    <origin
      xyz="0.03 0 0"
      rpy="0 0 0" />
    <parent
      link="leg4_link2" />
    <child
      link="leg4_link3" />
    <axis
      xyz="0 0 1" />
    <limit
      lower="-3.14"
      upper="3.14"
      effort="10"
      velocity="10" />
  </joint>
  <link
    name="leg5_link1">
    <inertial>
      <origin
        xyz="0.01 0.00025 0.0150000000000002"
        rpy="0 0 0" />
      <mass
        value="0.0003" />
      <inertia
        ixx="2.250625E-08"
        ixy="-3.47132410054955E-27"
        ixz="-1.21290162903837E-23"
        iyy="3.25E-08"
        iyz="-9.51731954659145E-27"
        izz="1.000625E-08" />
    </inertial>
    <visual>
      <origin
        xyz="0 0 0"
        rpy="0 0 0" />
      <geometry>
        <mesh
          filename="package://brdl-millihexapod-ros/meshes/leg5_link1.STL" />
      </geometry>
      <material
        name="">
        <color
          rgba="0.792156862745098 0.819607843137255 0.933333333333333 1" />
      </material>
    </visual>
    <collision>
      <origin
        xyz="0 0 0"
        rpy="0 0 0" />
      <geometry>
        <mesh
          filename="package://brdl-millihexapod-ros/meshes/leg5_link1.STL" />
      </geometry>
    </collision>
  </link>
  <joint
    name="torso__leg5_link1"
    type="revolute">
    <origin
      xyz="0.01309 0 -0.05"
      rpy="3.1416 1.5708 0" />
    <parent
      link="torso" />
    <child
      link="leg5_link1" />
    <axis
      xyz="0 0 1" />
    <limit
      lower="-3.14"
      upper="3.14"
      effort="10"
      velocity="10" />
  </joint>
  <link
    name="leg5_link2">
    <inertial>
      <origin
        xyz="0.015 0.000249999999999999 -0.01"
        rpy="0 0 0" />
      <mass
        value="0.0003" />
      <inertia
        ixx="1.000625E-08"
        ixy="-1.23171026920935E-26"
        ixz="-4.72810530077302E-24"
        iyy="3.25E-08"
        iyz="-1.13524817965326E-24"
        izz="2.250625E-08" />
    </inertial>
    <visual>
      <origin
        xyz="0 0 0"
        rpy="0 0 0" />
      <geometry>
        <mesh
          filename="package://brdl-millihexapod-ros/meshes/leg5_link2.STL" />
      </geometry>
      <material
        name="">
        <color
          rgba="0.792156862745098 0.819607843137255 0.933333333333333 1" />
      </material>
    </visual>
    <collision>
      <origin
        xyz="0 0 0"
        rpy="0 0 0" />
      <geometry>
        <mesh
          filename="package://brdl-millihexapod-ros/meshes/leg5_link2.STL" />
      </geometry>
    </collision>
  </link>
  <joint
    name="leg5_link1__leg5_link2"
    type="revolute">
    <origin
      xyz="0.005 0 0"
      rpy="0 0 0" />
    <parent
      link="leg5_link1" />
    <child
      link="leg5_link2" />
    <axis
      xyz="1 0 0" />
    <limit
      lower="-3.14"
      upper="3.14"
      effort="10"
      velocity="10" />
  </joint>
  <link
    name="leg5_link3">
    <inertial>
      <origin
        xyz="0.0175 0.000250000000000004 -0.00999999999999995"
        rpy="0 0 0" />
      <mass
        value="0.00035" />
      <inertia
        ixx="1.16739583333333E-08"
        ixy="7.76226710305203E-26"
        ixz="-1.23174588384869E-23"
        iyy="4.73958333333332E-08"
        iyz="-6.3275545756404E-25"
        izz="3.57364583333332E-08" />
    </inertial>
    <visual>
      <origin
        xyz="0 0 0"
        rpy="0 0 0" />
      <geometry>
        <mesh
          filename="package://brdl-millihexapod-ros/meshes/leg5_link3.STL" />
      </geometry>
      <material
        name="">
        <color
          rgba="0.792156862745098 0.819607843137255 0.933333333333333 1" />
      </material>
    </visual>
    <collision>
      <origin
        xyz="0 0 0"
        rpy="0 0 0" />
      <geometry>
        <mesh
          filename="package://brdl-millihexapod-ros/meshes/leg5_link3.STL" />
      </geometry>
    </collision>
  </link>
  <joint
    name="leg5_link2__leg5_link3"
    type="revolute">
    <origin
      xyz="0.03 0 0"
      rpy="0 0 0" />
    <parent
      link="leg5_link2" />
    <child
      link="leg5_link3" />
    <axis
      xyz="0 0 1" />
    <limit
      lower="-3.14"
      upper="3.14"
      effort="10"
      velocity="10" />
  </joint>
  <link
    name="leg6_link1">
    <inertial>
      <origin
        xyz="0.01 0.00025 0.0150000000000001"
        rpy="0 0 0" />
      <mass
        value="0.0003" />
      <inertia
        ixx="2.250625E-08"
        ixy="-1.20877888146441E-26"
        ixz="-8.62437511944734E-24"
        iyy="3.25E-08"
        iyz="2.49485393097846E-26"
        izz="1.000625E-08" />
    </inertial>
    <visual>
      <origin
        xyz="0 0 0"
        rpy="0 0 0" />
      <geometry>
        <mesh
          filename="package://brdl-millihexapod-ros/meshes/leg6_link1.STL" />
      </geometry>
      <material
        name="">
        <color
          rgba="0.792156862745098 0.819607843137255 0.933333333333333 1" />
      </material>
    </visual>
    <collision>
      <origin
        xyz="0 0 0"
        rpy="0 0 0" />
      <geometry>
        <mesh
          filename="package://brdl-millihexapod-ros/meshes/leg6_link1.STL" />
      </geometry>
    </collision>
  </link>
  <joint
    name="torso__leg6_link1"
    type="revolute">
    <origin
      xyz="-0.04691 0 -0.05"
      rpy="3.1416 1.5708 0" />
    <parent
      link="torso" />
    <child
      link="leg6_link1" />
    <axis
      xyz="0 0 1" />
    <limit
      lower="-3.14"
      upper="3.14"
      effort="10"
      velocity="10" />
  </joint>
  <link
    name="leg6_link2">
    <inertial>
      <origin
        xyz="0.015 0.00025 -0.01"
        rpy="0 0 0" />
      <mass
        value="0.0003" />
      <inertia
        ixx="1.000625E-08"
        ixy="-2.09335674062296E-26"
        ixz="-1.55399232424217E-23"
        iyy="3.25E-08"
        iyz="-1.0996695422915E-24"
        izz="2.250625E-08" />
    </inertial>
    <visual>
      <origin
        xyz="0 0 0"
        rpy="0 0 0" />
      <geometry>
        <mesh
          filename="package://brdl-millihexapod-ros/meshes/leg6_link2.STL" />
      </geometry>
      <material
        name="">
        <color
          rgba="0.792156862745098 0.819607843137255 0.933333333333333 1" />
      </material>
    </visual>
    <collision>
      <origin
        xyz="0 0 0"
        rpy="0 0 0" />
      <geometry>
        <mesh
          filename="package://brdl-millihexapod-ros/meshes/leg6_link2.STL" />
      </geometry>
    </collision>
  </link>
  <joint
    name="leg6_link1__leg6_link2"
    type="revolute">
    <origin
      xyz="0.005 0 0"
      rpy="0 0 0" />
    <parent
      link="leg6_link1" />
    <child
      link="leg6_link2" />
    <axis
      xyz="1 0 0" />
    <limit
      lower="-3.14"
      upper="3.14"
      effort="10"
      velocity="10" />
  </joint>
  <link
    name="leg6_link3">
    <inertial>
      <origin
        xyz="0.0175 0.000249999999999999 -0.00999999999999995"
        rpy="0 0 0" />
      <mass
        value="0.00035" />
      <inertia
        ixx="1.16739583333333E-08"
        ixy="6.03897416017412E-26"
        ixz="-7.21717523682009E-24"
        iyy="4.73958333333332E-08"
        iyz="1.40490250845733E-24"
        izz="3.57364583333332E-08" />
    </inertial>
    <visual>
      <origin
        xyz="0 0 0"
        rpy="0 0 0" />
      <geometry>
        <mesh
          filename="package://brdl-millihexapod-ros/meshes/leg6_link3.STL" />
      </geometry>
      <material
        name="">
        <color
          rgba="0.792156862745098 0.819607843137255 0.933333333333333 1" />
      </material>
    </visual>
    <collision>
      <origin
        xyz="0 0 0"
        rpy="0 0 0" />
      <geometry>
        <mesh
          filename="package://brdl-millihexapod-ros/meshes/leg6_link3.STL" />
      </geometry>
    </collision>
  </link>
  <joint
    name="leg6_link2__leg6_link3"
    type="revolute">
    <origin
      xyz="0.03 0 0"
      rpy="0 0 0" />
    <parent
      link="leg6_link2" />
    <child
      link="leg6_link3" />
    <axis
      xyz="0 0 1" />
    <limit
      lower="-3.14"
      upper="3.14"
      effort="10"
      velocity="10" />
  </joint>
</robot>